Thu, 02 Jan 2020 07:14:45 - INFO - Connect to DB
Thu, 02 Jan 2020 07:14:46 - ERROR - Exception on /records [GET]
Traceback (most recent call last):
  File "/home/python_project/hello.py", line 80, in get
    int(agent),
ValueError: invalid literal for int() with base 10: ''

During handling of the above exception, another exception occurred:

Traceback (most recent call last):
  File "/usr/local/lib/python3.6/dist-packages/flask/app.py", line 1949, in full_dispatch_request
    rv = self.dispatch_request()
  File "/usr/local/lib/python3.6/dist-packages/flask/app.py", line 1935, in dispatch_request
    return self.view_functions[rule.endpoint](**req.view_args)
  File "/usr/local/lib/python3.6/dist-packages/flask_restful/__init__.py", line 458, in wrapper
    resp = resource(*args, **kwargs)
  File "/usr/local/lib/python3.6/dist-packages/flask/views.py", line 89, in view
    return self.dispatch_request(*args, **kwargs)
  File "/usr/local/lib/python3.6/dist-packages/flask_restful/__init__.py", line 573, in dispatch_request
    resp = meth(*args, **kwargs)
  File "/home/python_project/hello.py", line 90, in get
    + str(e))
UnboundLocalError: local variable 'agentUsername' referenced before assignment
Thu, 02 Jan 2020 07:20:58 - INFO - Connect to DB
Thu, 02 Jan 2020 07:20:58 - INFO - TRIZMA DB import
Thu, 02 Jan 2020 07:20:58 - INFO - 123TV DB import
Thu, 02 Jan 2020 07:21:08 - INFO - Connect to DB
Thu, 02 Jan 2020 07:21:08 - INFO - TRIZMA DB import
Thu, 02 Jan 2020 07:21:08 - INFO - 123TV DB import
Thu, 02 Jan 2020 07:21:35 - INFO - Connect to DB
Thu, 02 Jan 2020 07:21:35 - INFO - TRIZMA DB import
Thu, 02 Jan 2020 07:21:35 - INFO - 123TV DB import
Thu, 02 Jan 2020 07:26:09 - INFO - Connect to DB
Thu, 02 Jan 2020 07:26:09 - INFO - TRIZMA DB import
Thu, 02 Jan 2020 07:26:09 - INFO - 123TV DB import
Thu, 02 Jan 2020 07:27:18 - INFO - Connect to DB
Thu, 02 Jan 2020 07:27:18 - INFO - TRIZMA DB import
Thu, 02 Jan 2020 07:27:18 - INFO - 123TV DB import
Thu, 02 Jan 2020 07:35:59 - INFO - Connect to DB
Thu, 02 Jan 2020 07:36:00 - INFO - TRIZMA DB import
Thu, 02 Jan 2020 07:36:00 - INFO - 123TV DB import
Thu, 02 Jan 2020 07:36:47 - INFO - Connect to DB
Thu, 02 Jan 2020 07:36:47 - INFO - TRIZMA DB import
Thu, 02 Jan 2020 07:36:47 - INFO - Failed on TRIZMA DB import at: 2020-01-02_07-12-01, for following calling party: 4951413012202, for agent id: trz_sstankovic, with error:(pyodbc.DataError) ('22001', '[22001] [Microsoft][ODBC Driver 17 for SQL Server][SQL Server]String or binary data would be truncated. (8152) (SQLExecDirectW)')
[SQL: insert into records values('CC2Servicenummer','Belgrad','Nicht übermittelt','trz_sstankovic',                                  '4951413012202','','Nicht übermittelt','4951413012202_Tuesday, December 31, 2019_9:40:28 AM')]
(Background on this error at: http://sqlalche.me/e/9h9h)
Thu, 02 Jan 2020 07:36:47 - INFO - 123TV DB import
Thu, 02 Jan 2020 07:37:27 - INFO - Connect to DB
Thu, 02 Jan 2020 07:37:27 - INFO - TRIZMA DB import
Thu, 02 Jan 2020 07:37:27 - INFO - 123TV DB import
Thu, 02 Jan 2020 07:40:49 - INFO - Connect to DB
Thu, 02 Jan 2020 07:40:49 - INFO - TRIZMA DB import
Thu, 02 Jan 2020 07:40:49 - INFO - 123TV DB import
Thu, 02 Jan 2020 07:41:26 - INFO - Connect to DB
Thu, 02 Jan 2020 07:41:26 - INFO - TRIZMA DB import
Thu, 02 Jan 2020 07:41:26 - INFO - 123TV DB import
Thu, 02 Jan 2020 07:42:06 - INFO - Connect to DB
Thu, 02 Jan 2020 07:42:06 - INFO - TRIZMA DB import
Thu, 02 Jan 2020 07:42:06 - INFO - 123TV DB import
Thu, 02 Jan 2020 07:50:24 - INFO - Connect to DB
Thu, 02 Jan 2020 07:50:24 - INFO - TRIZMA DB import
Thu, 02 Jan 2020 07:50:24 - INFO - 123TV DB import
Thu, 02 Jan 2020 07:52:18 - INFO - Connect to DB
Thu, 02 Jan 2020 07:52:18 - INFO - TRIZMA DB import
Thu, 02 Jan 2020 07:52:18 - INFO - 123TV DB import
