Thu, 19 Dec 2019 16:10:24 - INFO - Connect to DB
Thu, 19 Dec 2019 16:10:25 - INFO - TRIZMA DB import
Thu, 19 Dec 2019 16:10:25 - INFO - Failed on TRIZMA DB import at: 2019-12-19_14-23-50, for following calling party: 4964417897798, for agent id: trz_sstankovic, with error:(pyodbc.DataError) ('22001', '[22001] [Microsoft][ODBC Driver 17 for SQL Server][SQL Server]String or binary data would be truncated. (8152) (SQLExecDirectW)')
[SQL: insert into records values('CC2Servicenummer','Belgrad','Nicht 端bermittelt','trz_sstankovic',                                  '4964417897798','','Nicht 端bermittelt','4964417897798_Thursday, December 19, 2019_5:10:23 PM')]
(Background on this error at: http://sqlalche.me/e/9h9h)
Thu, 19 Dec 2019 16:10:25 - INFO - 123TV DB import
Thu, 19 Dec 2019 16:20:21 - INFO - Connect to DB
Thu, 19 Dec 2019 16:20:21 - INFO - TRIZMA DB import
Thu, 19 Dec 2019 16:20:21 - INFO - Failed on TRIZMA DB import at: 2019-12-19_14-23-50, for following calling party: 494213808110, for agent id: trz_sstankovic, with error:(pyodbc.DataError) ('22001', '[22001] [Microsoft][ODBC Driver 17 for SQL Server][SQL Server]String or binary data would be truncated. (8152) (SQLExecDirectW)')
[SQL: insert into records values('CC2Servicenummer','Belgrad','Nicht 端bermittelt','trz_sstankovic',                                  '494213808110','','Nicht 端bermittelt','494213808110_Thursday, December 19, 2019_5:20:19 PM')]
(Background on this error at: http://sqlalche.me/e/9h9h)
Thu, 19 Dec 2019 16:20:21 - INFO - 123TV DB import
Thu, 19 Dec 2019 16:21:26 - INFO - Connect to DB
Thu, 19 Dec 2019 16:21:26 - ERROR - Exception on /records [GET]
Traceback (most recent call last):
  File "/home/python_project/hello.py", line 80, in get
    int(agent),
ValueError: invalid literal for int() with base 10: ''

During handling of the above exception, another exception occurred:

Traceback (most recent call last):
  File "/usr/local/lib/python3.6/dist-packages/flask/app.py", line 1949, in full_dispatch_request
    rv = self.dispatch_request()
  File "/usr/local/lib/python3.6/dist-packages/flask/app.py", line 1935, in dispatch_request
    return self.view_functions[rule.endpoint](**req.view_args)
  File "/usr/local/lib/python3.6/dist-packages/flask_restful/__init__.py", line 458, in wrapper
    resp = resource(*args, **kwargs)
  File "/usr/local/lib/python3.6/dist-packages/flask/views.py", line 89, in view
    return self.dispatch_request(*args, **kwargs)
  File "/usr/local/lib/python3.6/dist-packages/flask_restful/__init__.py", line 573, in dispatch_request
    resp = meth(*args, **kwargs)
  File "/home/python_project/hello.py", line 90, in get
    + str(e))
UnboundLocalError: local variable 'agentUsername' referenced before assignment
Thu, 19 Dec 2019 16:21:51 - INFO - Connect to DB
Thu, 19 Dec 2019 16:21:51 - INFO - TRIZMA DB import
Thu, 19 Dec 2019 16:21:51 - INFO - 123TV DB import
Thu, 19 Dec 2019 16:21:56 - INFO - Connect to DB
Thu, 19 Dec 2019 16:21:56 - INFO - TRIZMA DB import
Thu, 19 Dec 2019 16:21:56 - INFO - 123TV DB import
