Wed, 18 Dec 2019 18:07:29 - INFO - Connect to DB
Wed, 18 Dec 2019 18:07:30 - INFO - TRIZMA DB import
Wed, 18 Dec 2019 18:07:30 - INFO - 123TV DB import
Wed, 18 Dec 2019 19:22:56 - INFO - Connect to DB
Wed, 18 Dec 2019 19:22:56 - INFO - TRIZMA DB import
Wed, 18 Dec 2019 19:22:56 - INFO - 123TV DB import
Thu, 19 Dec 2019 06:55:53 - INFO - Connect to DB
Thu, 19 Dec 2019 06:55:53 - INFO - TRIZMA DB import
Thu, 19 Dec 2019 06:55:53 - INFO - 123TV DB import
Thu, 19 Dec 2019 06:55:58 - INFO - Failed on 123TV DB import at: 2019-12-18_17-21-31, for following calling party: %m, for agent id: 3098, with error:Call to undefined method ImportCallMetaData::Message()
Thu, 19 Dec 2019 07:40:22 - INFO - Connect to DB
Thu, 19 Dec 2019 07:40:22 - INFO - TRIZMA DB import
Thu, 19 Dec 2019 07:40:22 - INFO - 123TV DB import
Thu, 19 Dec 2019 07:40:27 - INFO - Failed on 123TV DB import at: 2019-12-18_17-21-31, for following calling party: %m, for agent id: 3036, with error:Call to undefined method ImportCallMetaData::Message()
Thu, 19 Dec 2019 07:40:27 - INFO - Connect to DB
Thu, 19 Dec 2019 07:40:27 - INFO - TRIZMA DB import
Thu, 19 Dec 2019 07:40:27 - INFO - 123TV DB import
Thu, 19 Dec 2019 07:40:32 - INFO - Failed on 123TV DB import at: 2019-12-18_17-21-31, for following calling party: %m, for agent id: 3065, with error:Call to undefined method ImportCallMetaData::Message()
Thu, 19 Dec 2019 07:43:15 - INFO - Connect to DB
Thu, 19 Dec 2019 07:43:15 - ERROR - Exception on /records [GET]
Traceback (most recent call last):
  File "/home/python_project/hello.py", line 81, in get
    1)).fetchone()[0]
TypeError: 'NoneType' object is not subscriptable

During handling of the above exception, another exception occurred:

Traceback (most recent call last):
  File "/usr/local/lib/python3.6/dist-packages/flask/app.py", line 1949, in full_dispatch_request
    rv = self.dispatch_request()
  File "/usr/local/lib/python3.6/dist-packages/flask/app.py", line 1935, in dispatch_request
    return self.view_functions[rule.endpoint](**req.view_args)
  File "/usr/local/lib/python3.6/dist-packages/flask_restful/__init__.py", line 458, in wrapper
    resp = resource(*args, **kwargs)
  File "/usr/local/lib/python3.6/dist-packages/flask/views.py", line 89, in view
    return self.dispatch_request(*args, **kwargs)
  File "/usr/local/lib/python3.6/dist-packages/flask_restful/__init__.py", line 573, in dispatch_request
    resp = meth(*args, **kwargs)
  File "/home/python_project/hello.py", line 90, in get
    + str(e))
UnboundLocalError: local variable 'agentUsername' referenced before assignment
Thu, 19 Dec 2019 08:16:57 - INFO - Connect to DB
Thu, 19 Dec 2019 08:16:57 - INFO - TRIZMA DB import
Thu, 19 Dec 2019 08:16:57 - INFO - 123TV DB import
Thu, 19 Dec 2019 08:17:02 - INFO - Failed on 123TV DB import at: 2019-12-18_17-21-31, for following calling party: %m, for agent id: 3182, with error:Call to undefined method ImportCallMetaData::Message()
