Sat, 28 Dec 2019 12:42:26 - INFO - Connect to DB
Sat, 28 Dec 2019 12:42:27 - INFO - TRIZMA DB import
Sat, 28 Dec 2019 12:42:27 - INFO - 123TV DB import
Sat, 28 Dec 2019 12:54:06 - INFO - Connect to DB
Sat, 28 Dec 2019 12:54:06 - INFO - TRIZMA DB import
Sat, 28 Dec 2019 12:54:06 - INFO - 123TV DB import
Sat, 28 Dec 2019 13:01:15 - INFO - Connect to DB
Sat, 28 Dec 2019 13:01:15 - INFO - TRIZMA DB import
Sat, 28 Dec 2019 13:01:15 - INFO - Failed on TRIZMA DB import at: 2019-12-28_12-32-08, for following calling party: 4962065804895, for agent id: trz_tjurjevic, with error:(pyodbc.DataError) ('22001', '[22001] [Microsoft][ODBC Driver 17 for SQL Server][SQL Server]String or binary data would be truncated. (8152) (SQLExecDirectW)')
[SQL: insert into records values('CC2Servicenummer','Belgrad','Nicht 端bermittelt','trz_tjurjevic',                                  '4962065804895','','Nicht 端bermittelt','4962065804895_Saturday, December 28, 2019_2:01:12 PM')]
(Background on this error at: http://sqlalche.me/e/9h9h)
Sat, 28 Dec 2019 13:01:15 - INFO - 123TV DB import
Sat, 28 Dec 2019 13:29:47 - INFO - Connect to DB
Sat, 28 Dec 2019 13:29:47 - ERROR - Exception on /records [GET]
Traceback (most recent call last):
  File "/usr/local/lib/python3.6/dist-packages/sqlalchemy/engine/base.py", line 1246, in _execute_context
    cursor, statement, parameters, context
  File "/usr/local/lib/python3.6/dist-packages/sqlalchemy/engine/default.py", line 581, in do_execute
    cursor.execute(statement, parameters)
pyodbc.OperationalError: ('08S01', '[08S01] [Microsoft][ODBC Driver 17 for SQL Server]TCP Provider: Error code 0x274C (10060) (SQLExecDirectW)')

The above exception was the direct cause of the following exception:

Traceback (most recent call last):
  File "/home/python_project/hello.py", line 81, in get
    1)).fetchone()[0]
  File "/usr/local/lib/python3.6/dist-packages/sqlalchemy/engine/base.py", line 976, in execute
    return self._execute_text(object_, multiparams, params)
  File "/usr/local/lib/python3.6/dist-packages/sqlalchemy/engine/base.py", line 1149, in _execute_text
    parameters,
  File "/usr/local/lib/python3.6/dist-packages/sqlalchemy/engine/base.py", line 1250, in _execute_context
    e, statement, parameters, cursor, context
  File "/usr/local/lib/python3.6/dist-packages/sqlalchemy/engine/base.py", line 1476, in _handle_dbapi_exception
    util.raise_from_cause(sqlalchemy_exception, exc_info)
  File "/usr/local/lib/python3.6/dist-packages/sqlalchemy/util/compat.py", line 398, in raise_from_cause
    reraise(type(exception), exception, tb=exc_tb, cause=cause)
  File "/usr/local/lib/python3.6/dist-packages/sqlalchemy/util/compat.py", line 152, in reraise
    raise value.with_traceback(tb)
  File "/usr/local/lib/python3.6/dist-packages/sqlalchemy/engine/base.py", line 1246, in _execute_context
    cursor, statement, parameters, context
  File "/usr/local/lib/python3.6/dist-packages/sqlalchemy/engine/default.py", line 581, in do_execute
    cursor.execute(statement, parameters)
sqlalchemy.exc.OperationalError: (pyodbc.OperationalError) ('08S01', '[08S01] [Microsoft][ODBC Driver 17 for SQL Server]TCP Provider: Error code 0x274C (10060) (SQLExecDirectW)')
[SQL: select qmUser from dimAgents where cmsID = 3191 and active = 1]
(Background on this error at: http://sqlalche.me/e/e3q8)

During handling of the above exception, another exception occurred:

Traceback (most recent call last):
  File "/usr/local/lib/python3.6/dist-packages/flask/app.py", line 1949, in full_dispatch_request
    rv = self.dispatch_request()
  File "/usr/local/lib/python3.6/dist-packages/flask/app.py", line 1935, in dispatch_request
    return self.view_functions[rule.endpoint](**req.view_args)
  File "/usr/local/lib/python3.6/dist-packages/flask_restful/__init__.py", line 458, in wrapper
    resp = resource(*args, **kwargs)
  File "/usr/local/lib/python3.6/dist-packages/flask/views.py", line 89, in view
    return self.dispatch_request(*args, **kwargs)
  File "/usr/local/lib/python3.6/dist-packages/flask_restful/__init__.py", line 573, in dispatch_request
    resp = meth(*args, **kwargs)
  File "/home/python_project/hello.py", line 90, in get
    + str(e))
UnboundLocalError: local variable 'agentUsername' referenced before assignment
Sat, 28 Dec 2019 13:38:53 - INFO - Connect to DB
Sat, 28 Dec 2019 13:38:53 - INFO - TRIZMA DB import
Sat, 28 Dec 2019 13:38:53 - INFO - Failed on TRIZMA DB import at: 2019-12-28_12-32-08, for following calling party: 491738073304, for agent id: trz_mglisic, with error:(pyodbc.DataError) ('22001', '[22001] [Microsoft][ODBC Driver 17 for SQL Server][SQL Server]String or binary data would be truncated. (8152) (SQLExecDirectW)')
[SQL: insert into records values('CC2Servicenummer','Belgrad','Nicht 端bermittelt','trz_mglisic',                                  '491738073304','','Nicht 端bermittelt','491738073304_Saturday, December 28, 2019_2:38:51 PM')]
(Background on this error at: http://sqlalche.me/e/9h9h)
Sat, 28 Dec 2019 13:38:53 - INFO - 123TV DB import
