Mon, 16 Dec 2019 16:44:55 - INFO -  * Running on http://0.0.0.0:5001/ (Press CTRL+C to quit)
Mon, 16 Dec 2019 16:44:57 - INFO - 109.245.208.129 - - [16/Dec/2019 16:44:57] "GET / HTTP/1.1" 200 -
Mon, 16 Dec 2019 16:45:14 - INFO - Connect to DB
Mon, 16 Dec 2019 16:45:14 - ERROR - Exception on /records [GET]
Traceback (most recent call last):
  File "/usr/local/lib/python3.6/dist-packages/sqlalchemy/engine/base.py", line 2276, in _wrap_pool_connect
    return fn()
  File "/usr/local/lib/python3.6/dist-packages/sqlalchemy/pool/base.py", line 303, in unique_connection
    return _ConnectionFairy._checkout(self)
  File "/usr/local/lib/python3.6/dist-packages/sqlalchemy/pool/base.py", line 760, in _checkout
    fairy = _ConnectionRecord.checkout(pool)
  File "/usr/local/lib/python3.6/dist-packages/sqlalchemy/pool/base.py", line 492, in checkout
    rec = pool._do_get()
  File "/usr/local/lib/python3.6/dist-packages/sqlalchemy/pool/impl.py", line 139, in _do_get
    self._dec_overflow()
  File "/usr/local/lib/python3.6/dist-packages/sqlalchemy/util/langhelpers.py", line 68, in __exit__
    compat.reraise(exc_type, exc_value, exc_tb)
  File "/usr/local/lib/python3.6/dist-packages/sqlalchemy/util/compat.py", line 153, in reraise
    raise value
  File "/usr/local/lib/python3.6/dist-packages/sqlalchemy/pool/impl.py", line 136, in _do_get
    return self._create_connection()
  File "/usr/local/lib/python3.6/dist-packages/sqlalchemy/pool/base.py", line 308, in _create_connection
    return _ConnectionRecord(self)
  File "/usr/local/lib/python3.6/dist-packages/sqlalchemy/pool/base.py", line 437, in __init__
    self.__connect(first_connect_check=True)
  File "/usr/local/lib/python3.6/dist-packages/sqlalchemy/pool/base.py", line 639, in __connect
    connection = pool._invoke_creator(self)
  File "/usr/local/lib/python3.6/dist-packages/sqlalchemy/engine/strategies.py", line 114, in connect
    return dialect.connect(*cargs, **cparams)
  File "/usr/local/lib/python3.6/dist-packages/sqlalchemy/engine/default.py", line 482, in connect
    return self.dbapi.connect(*cargs, **cparams)
pyodbc.Error: ('01000', "[01000] [unixODBC][Driver Manager]Can't open lib 'SQL Server Native Client 11.0' : file not found (0) (SQLDriverConnect)")

The above exception was the direct cause of the following exception:

Traceback (most recent call last):
  File "/home/python_project/hello.py", line 74, in get
    conn = db_connect.connect()
  File "/usr/local/lib/python3.6/dist-packages/sqlalchemy/engine/base.py", line 2209, in connect
    return self._connection_cls(self, **kwargs)
  File "/usr/local/lib/python3.6/dist-packages/sqlalchemy/engine/base.py", line 103, in __init__
    else engine.raw_connection()
  File "/usr/local/lib/python3.6/dist-packages/sqlalchemy/engine/base.py", line 2307, in raw_connection
    self.pool.unique_connection, _connection
  File "/usr/local/lib/python3.6/dist-packages/sqlalchemy/engine/base.py", line 2280, in _wrap_pool_connect
    e, dialect, self
  File "/usr/local/lib/python3.6/dist-packages/sqlalchemy/engine/base.py", line 1547, in _handle_dbapi_exception_noconnection
    util.raise_from_cause(sqlalchemy_exception, exc_info)
  File "/usr/local/lib/python3.6/dist-packages/sqlalchemy/util/compat.py", line 398, in raise_from_cause
    reraise(type(exception), exception, tb=exc_tb, cause=cause)
  File "/usr/local/lib/python3.6/dist-packages/sqlalchemy/util/compat.py", line 152, in reraise
    raise value.with_traceback(tb)
  File "/usr/local/lib/python3.6/dist-packages/sqlalchemy/engine/base.py", line 2276, in _wrap_pool_connect
    return fn()
  File "/usr/local/lib/python3.6/dist-packages/sqlalchemy/pool/base.py", line 303, in unique_connection
    return _ConnectionFairy._checkout(self)
  File "/usr/local/lib/python3.6/dist-packages/sqlalchemy/pool/base.py", line 760, in _checkout
    fairy = _ConnectionRecord.checkout(pool)
  File "/usr/local/lib/python3.6/dist-packages/sqlalchemy/pool/base.py", line 492, in checkout
    rec = pool._do_get()
  File "/usr/local/lib/python3.6/dist-packages/sqlalchemy/pool/impl.py", line 139, in _do_get
    self._dec_overflow()
  File "/usr/local/lib/python3.6/dist-packages/sqlalchemy/util/langhelpers.py", line 68, in __exit__
    compat.reraise(exc_type, exc_value, exc_tb)
  File "/usr/local/lib/python3.6/dist-packages/sqlalchemy/util/compat.py", line 153, in reraise
    raise value
  File "/usr/local/lib/python3.6/dist-packages/sqlalchemy/pool/impl.py", line 136, in _do_get
    return self._create_connection()
  File "/usr/local/lib/python3.6/dist-packages/sqlalchemy/pool/base.py", line 308, in _create_connection
    return _ConnectionRecord(self)
  File "/usr/local/lib/python3.6/dist-packages/sqlalchemy/pool/base.py", line 437, in __init__
    self.__connect(first_connect_check=True)
  File "/usr/local/lib/python3.6/dist-packages/sqlalchemy/pool/base.py", line 639, in __connect
    connection = pool._invoke_creator(self)
  File "/usr/local/lib/python3.6/dist-packages/sqlalchemy/engine/strategies.py", line 114, in connect
    return dialect.connect(*cargs, **cparams)
  File "/usr/local/lib/python3.6/dist-packages/sqlalchemy/engine/default.py", line 482, in connect
    return self.dbapi.connect(*cargs, **cparams)
sqlalchemy.exc.DBAPIError: (pyodbc.Error) ('01000', "[01000] [unixODBC][Driver Manager]Can't open lib 'SQL Server Native Client 11.0' : file not found (0) (SQLDriverConnect)")
(Background on this error at: http://sqlalche.me/e/dbapi)

During handling of the above exception, another exception occurred:

Traceback (most recent call last):
  File "/usr/local/lib/python3.6/dist-packages/flask/app.py", line 1949, in full_dispatch_request
    rv = self.dispatch_request()
  File "/usr/local/lib/python3.6/dist-packages/flask/app.py", line 1935, in dispatch_request
    return self.view_functions[rule.endpoint](**req.view_args)
  File "/usr/local/lib/python3.6/dist-packages/flask_restful/__init__.py", line 458, in wrapper
    resp = resource(*args, **kwargs)
  File "/usr/local/lib/python3.6/dist-packages/flask/views.py", line 89, in view
    return self.dispatch_request(*args, **kwargs)
  File "/usr/local/lib/python3.6/dist-packages/flask_restful/__init__.py", line 573, in dispatch_request
    resp = meth(*args, **kwargs)
  File "/home/python_project/hello.py", line 88, in get
    + str(e))
UnboundLocalError: local variable 'agentUsername' referenced before assignment
Mon, 16 Dec 2019 16:45:14 - INFO - 109.245.208.129 - - [16/Dec/2019 16:45:14] "GET /records?agent=3016&caller_id=38163353865&date=20191120&time=140203 HTTP/1.1" 500 -
Mon, 16 Dec 2019 16:45:17 - INFO - Connect to DB
Mon, 16 Dec 2019 16:45:17 - ERROR - Exception on /records [GET]
Traceback (most recent call last):
  File "/usr/local/lib/python3.6/dist-packages/sqlalchemy/engine/base.py", line 2276, in _wrap_pool_connect
    return fn()
  File "/usr/local/lib/python3.6/dist-packages/sqlalchemy/pool/base.py", line 303, in unique_connection
    return _ConnectionFairy._checkout(self)
  File "/usr/local/lib/python3.6/dist-packages/sqlalchemy/pool/base.py", line 760, in _checkout
    fairy = _ConnectionRecord.checkout(pool)
  File "/usr/local/lib/python3.6/dist-packages/sqlalchemy/pool/base.py", line 492, in checkout
    rec = pool._do_get()
  File "/usr/local/lib/python3.6/dist-packages/sqlalchemy/pool/impl.py", line 139, in _do_get
    self._dec_overflow()
  File "/usr/local/lib/python3.6/dist-packages/sqlalchemy/util/langhelpers.py", line 68, in __exit__
    compat.reraise(exc_type, exc_value, exc_tb)
  File "/usr/local/lib/python3.6/dist-packages/sqlalchemy/util/compat.py", line 153, in reraise
    raise value
  File "/usr/local/lib/python3.6/dist-packages/sqlalchemy/pool/impl.py", line 136, in _do_get
    return self._create_connection()
  File "/usr/local/lib/python3.6/dist-packages/sqlalchemy/pool/base.py", line 308, in _create_connection
    return _ConnectionRecord(self)
  File "/usr/local/lib/python3.6/dist-packages/sqlalchemy/pool/base.py", line 437, in __init__
    self.__connect(first_connect_check=True)
  File "/usr/local/lib/python3.6/dist-packages/sqlalchemy/pool/base.py", line 639, in __connect
    connection = pool._invoke_creator(self)
  File "/usr/local/lib/python3.6/dist-packages/sqlalchemy/engine/strategies.py", line 114, in connect
    return dialect.connect(*cargs, **cparams)
  File "/usr/local/lib/python3.6/dist-packages/sqlalchemy/engine/default.py", line 482, in connect
    return self.dbapi.connect(*cargs, **cparams)
pyodbc.Error: ('01000', "[01000] [unixODBC][Driver Manager]Can't open lib 'SQL Server Native Client 11.0' : file not found (0) (SQLDriverConnect)")

The above exception was the direct cause of the following exception:

Traceback (most recent call last):
  File "/home/python_project/hello.py", line 74, in get
    conn = db_connect.connect()
  File "/usr/local/lib/python3.6/dist-packages/sqlalchemy/engine/base.py", line 2209, in connect
    return self._connection_cls(self, **kwargs)
  File "/usr/local/lib/python3.6/dist-packages/sqlalchemy/engine/base.py", line 103, in __init__
    else engine.raw_connection()
  File "/usr/local/lib/python3.6/dist-packages/sqlalchemy/engine/base.py", line 2307, in raw_connection
    self.pool.unique_connection, _connection
  File "/usr/local/lib/python3.6/dist-packages/sqlalchemy/engine/base.py", line 2280, in _wrap_pool_connect
    e, dialect, self
  File "/usr/local/lib/python3.6/dist-packages/sqlalchemy/engine/base.py", line 1547, in _handle_dbapi_exception_noconnection
    util.raise_from_cause(sqlalchemy_exception, exc_info)
  File "/usr/local/lib/python3.6/dist-packages/sqlalchemy/util/compat.py", line 398, in raise_from_cause
    reraise(type(exception), exception, tb=exc_tb, cause=cause)
  File "/usr/local/lib/python3.6/dist-packages/sqlalchemy/util/compat.py", line 152, in reraise
    raise value.with_traceback(tb)
  File "/usr/local/lib/python3.6/dist-packages/sqlalchemy/engine/base.py", line 2276, in _wrap_pool_connect
    return fn()
  File "/usr/local/lib/python3.6/dist-packages/sqlalchemy/pool/base.py", line 303, in unique_connection
    return _ConnectionFairy._checkout(self)
  File "/usr/local/lib/python3.6/dist-packages/sqlalchemy/pool/base.py", line 760, in _checkout
    fairy = _ConnectionRecord.checkout(pool)
  File "/usr/local/lib/python3.6/dist-packages/sqlalchemy/pool/base.py", line 492, in checkout
    rec = pool._do_get()
  File "/usr/local/lib/python3.6/dist-packages/sqlalchemy/pool/impl.py", line 139, in _do_get
    self._dec_overflow()
  File "/usr/local/lib/python3.6/dist-packages/sqlalchemy/util/langhelpers.py", line 68, in __exit__
    compat.reraise(exc_type, exc_value, exc_tb)
  File "/usr/local/lib/python3.6/dist-packages/sqlalchemy/util/compat.py", line 153, in reraise
    raise value
  File "/usr/local/lib/python3.6/dist-packages/sqlalchemy/pool/impl.py", line 136, in _do_get
    return self._create_connection()
  File "/usr/local/lib/python3.6/dist-packages/sqlalchemy/pool/base.py", line 308, in _create_connection
    return _ConnectionRecord(self)
  File "/usr/local/lib/python3.6/dist-packages/sqlalchemy/pool/base.py", line 437, in __init__
    self.__connect(first_connect_check=True)
  File "/usr/local/lib/python3.6/dist-packages/sqlalchemy/pool/base.py", line 639, in __connect
    connection = pool._invoke_creator(self)
  File "/usr/local/lib/python3.6/dist-packages/sqlalchemy/engine/strategies.py", line 114, in connect
    return dialect.connect(*cargs, **cparams)
  File "/usr/local/lib/python3.6/dist-packages/sqlalchemy/engine/default.py", line 482, in connect
    return self.dbapi.connect(*cargs, **cparams)
sqlalchemy.exc.DBAPIError: (pyodbc.Error) ('01000', "[01000] [unixODBC][Driver Manager]Can't open lib 'SQL Server Native Client 11.0' : file not found (0) (SQLDriverConnect)")
(Background on this error at: http://sqlalche.me/e/dbapi)

During handling of the above exception, another exception occurred:

Traceback (most recent call last):
  File "/usr/local/lib/python3.6/dist-packages/flask/app.py", line 1949, in full_dispatch_request
    rv = self.dispatch_request()
  File "/usr/local/lib/python3.6/dist-packages/flask/app.py", line 1935, in dispatch_request
    return self.view_functions[rule.endpoint](**req.view_args)
  File "/usr/local/lib/python3.6/dist-packages/flask_restful/__init__.py", line 458, in wrapper
    resp = resource(*args, **kwargs)
  File "/usr/local/lib/python3.6/dist-packages/flask/views.py", line 89, in view
    return self.dispatch_request(*args, **kwargs)
  File "/usr/local/lib/python3.6/dist-packages/flask_restful/__init__.py", line 573, in dispatch_request
    resp = meth(*args, **kwargs)
  File "/home/python_project/hello.py", line 88, in get
    + str(e))
UnboundLocalError: local variable 'agentUsername' referenced before assignment
Mon, 16 Dec 2019 16:45:17 - INFO - 109.245.208.129 - - [16/Dec/2019 16:45:17] "GET /records?agent=3016&caller_id=38163353865&date=20191120&time=140203 HTTP/1.1" 500 -
Mon, 16 Dec 2019 16:45:18 - INFO - Connect to DB
Mon, 16 Dec 2019 16:45:18 - ERROR - Exception on /records [GET]
Traceback (most recent call last):
  File "/usr/local/lib/python3.6/dist-packages/sqlalchemy/engine/base.py", line 2276, in _wrap_pool_connect
    return fn()
  File "/usr/local/lib/python3.6/dist-packages/sqlalchemy/pool/base.py", line 303, in unique_connection
    return _ConnectionFairy._checkout(self)
  File "/usr/local/lib/python3.6/dist-packages/sqlalchemy/pool/base.py", line 760, in _checkout
    fairy = _ConnectionRecord.checkout(pool)
  File "/usr/local/lib/python3.6/dist-packages/sqlalchemy/pool/base.py", line 492, in checkout
    rec = pool._do_get()
  File "/usr/local/lib/python3.6/dist-packages/sqlalchemy/pool/impl.py", line 139, in _do_get
    self._dec_overflow()
  File "/usr/local/lib/python3.6/dist-packages/sqlalchemy/util/langhelpers.py", line 68, in __exit__
    compat.reraise(exc_type, exc_value, exc_tb)
  File "/usr/local/lib/python3.6/dist-packages/sqlalchemy/util/compat.py", line 153, in reraise
    raise value
  File "/usr/local/lib/python3.6/dist-packages/sqlalchemy/pool/impl.py", line 136, in _do_get
    return self._create_connection()
  File "/usr/local/lib/python3.6/dist-packages/sqlalchemy/pool/base.py", line 308, in _create_connection
    return _ConnectionRecord(self)
  File "/usr/local/lib/python3.6/dist-packages/sqlalchemy/pool/base.py", line 437, in __init__
    self.__connect(first_connect_check=True)
  File "/usr/local/lib/python3.6/dist-packages/sqlalchemy/pool/base.py", line 639, in __connect
    connection = pool._invoke_creator(self)
  File "/usr/local/lib/python3.6/dist-packages/sqlalchemy/engine/strategies.py", line 114, in connect
    return dialect.connect(*cargs, **cparams)
  File "/usr/local/lib/python3.6/dist-packages/sqlalchemy/engine/default.py", line 482, in connect
    return self.dbapi.connect(*cargs, **cparams)
pyodbc.Error: ('01000', "[01000] [unixODBC][Driver Manager]Can't open lib 'SQL Server Native Client 11.0' : file not found (0) (SQLDriverConnect)")

The above exception was the direct cause of the following exception:

Traceback (most recent call last):
  File "/home/python_project/hello.py", line 74, in get
    conn = db_connect.connect()
  File "/usr/local/lib/python3.6/dist-packages/sqlalchemy/engine/base.py", line 2209, in connect
    return self._connection_cls(self, **kwargs)
  File "/usr/local/lib/python3.6/dist-packages/sqlalchemy/engine/base.py", line 103, in __init__
    else engine.raw_connection()
  File "/usr/local/lib/python3.6/dist-packages/sqlalchemy/engine/base.py", line 2307, in raw_connection
    self.pool.unique_connection, _connection
  File "/usr/local/lib/python3.6/dist-packages/sqlalchemy/engine/base.py", line 2280, in _wrap_pool_connect
    e, dialect, self
  File "/usr/local/lib/python3.6/dist-packages/sqlalchemy/engine/base.py", line 1547, in _handle_dbapi_exception_noconnection
    util.raise_from_cause(sqlalchemy_exception, exc_info)
  File "/usr/local/lib/python3.6/dist-packages/sqlalchemy/util/compat.py", line 398, in raise_from_cause
    reraise(type(exception), exception, tb=exc_tb, cause=cause)
  File "/usr/local/lib/python3.6/dist-packages/sqlalchemy/util/compat.py", line 152, in reraise
    raise value.with_traceback(tb)
  File "/usr/local/lib/python3.6/dist-packages/sqlalchemy/engine/base.py", line 2276, in _wrap_pool_connect
    return fn()
  File "/usr/local/lib/python3.6/dist-packages/sqlalchemy/pool/base.py", line 303, in unique_connection
    return _ConnectionFairy._checkout(self)
  File "/usr/local/lib/python3.6/dist-packages/sqlalchemy/pool/base.py", line 760, in _checkout
    fairy = _ConnectionRecord.checkout(pool)
  File "/usr/local/lib/python3.6/dist-packages/sqlalchemy/pool/base.py", line 492, in checkout
    rec = pool._do_get()
  File "/usr/local/lib/python3.6/dist-packages/sqlalchemy/pool/impl.py", line 139, in _do_get
    self._dec_overflow()
  File "/usr/local/lib/python3.6/dist-packages/sqlalchemy/util/langhelpers.py", line 68, in __exit__
    compat.reraise(exc_type, exc_value, exc_tb)
  File "/usr/local/lib/python3.6/dist-packages/sqlalchemy/util/compat.py", line 153, in reraise
    raise value
  File "/usr/local/lib/python3.6/dist-packages/sqlalchemy/pool/impl.py", line 136, in _do_get
    return self._create_connection()
  File "/usr/local/lib/python3.6/dist-packages/sqlalchemy/pool/base.py", line 308, in _create_connection
    return _ConnectionRecord(self)
  File "/usr/local/lib/python3.6/dist-packages/sqlalchemy/pool/base.py", line 437, in __init__
    self.__connect(first_connect_check=True)
  File "/usr/local/lib/python3.6/dist-packages/sqlalchemy/pool/base.py", line 639, in __connect
    connection = pool._invoke_creator(self)
  File "/usr/local/lib/python3.6/dist-packages/sqlalchemy/engine/strategies.py", line 114, in connect
    return dialect.connect(*cargs, **cparams)
  File "/usr/local/lib/python3.6/dist-packages/sqlalchemy/engine/default.py", line 482, in connect
    return self.dbapi.connect(*cargs, **cparams)
sqlalchemy.exc.DBAPIError: (pyodbc.Error) ('01000', "[01000] [unixODBC][Driver Manager]Can't open lib 'SQL Server Native Client 11.0' : file not found (0) (SQLDriverConnect)")
(Background on this error at: http://sqlalche.me/e/dbapi)

During handling of the above exception, another exception occurred:

Traceback (most recent call last):
  File "/usr/local/lib/python3.6/dist-packages/flask/app.py", line 1949, in full_dispatch_request
    rv = self.dispatch_request()
  File "/usr/local/lib/python3.6/dist-packages/flask/app.py", line 1935, in dispatch_request
    return self.view_functions[rule.endpoint](**req.view_args)
  File "/usr/local/lib/python3.6/dist-packages/flask_restful/__init__.py", line 458, in wrapper
    resp = resource(*args, **kwargs)
  File "/usr/local/lib/python3.6/dist-packages/flask/views.py", line 89, in view
    return self.dispatch_request(*args, **kwargs)
  File "/usr/local/lib/python3.6/dist-packages/flask_restful/__init__.py", line 573, in dispatch_request
    resp = meth(*args, **kwargs)
  File "/home/python_project/hello.py", line 88, in get
    + str(e))
UnboundLocalError: local variable 'agentUsername' referenced before assignment
Mon, 16 Dec 2019 16:45:18 - INFO - 109.245.208.129 - - [16/Dec/2019 16:45:18] "GET /records?agent=3016&caller_id=38163353865&date=20191120&time=140203 HTTP/1.1" 500 -
Mon, 16 Dec 2019 16:45:19 - INFO - Connect to DB
Mon, 16 Dec 2019 16:45:19 - ERROR - Exception on /records [GET]
Traceback (most recent call last):
  File "/usr/local/lib/python3.6/dist-packages/sqlalchemy/engine/base.py", line 2276, in _wrap_pool_connect
    return fn()
  File "/usr/local/lib/python3.6/dist-packages/sqlalchemy/pool/base.py", line 303, in unique_connection
    return _ConnectionFairy._checkout(self)
  File "/usr/local/lib/python3.6/dist-packages/sqlalchemy/pool/base.py", line 760, in _checkout
    fairy = _ConnectionRecord.checkout(pool)
  File "/usr/local/lib/python3.6/dist-packages/sqlalchemy/pool/base.py", line 492, in checkout
    rec = pool._do_get()
  File "/usr/local/lib/python3.6/dist-packages/sqlalchemy/pool/impl.py", line 139, in _do_get
    self._dec_overflow()
  File "/usr/local/lib/python3.6/dist-packages/sqlalchemy/util/langhelpers.py", line 68, in __exit__
    compat.reraise(exc_type, exc_value, exc_tb)
  File "/usr/local/lib/python3.6/dist-packages/sqlalchemy/util/compat.py", line 153, in reraise
    raise value
  File "/usr/local/lib/python3.6/dist-packages/sqlalchemy/pool/impl.py", line 136, in _do_get
    return self._create_connection()
  File "/usr/local/lib/python3.6/dist-packages/sqlalchemy/pool/base.py", line 308, in _create_connection
    return _ConnectionRecord(self)
  File "/usr/local/lib/python3.6/dist-packages/sqlalchemy/pool/base.py", line 437, in __init__
    self.__connect(first_connect_check=True)
  File "/usr/local/lib/python3.6/dist-packages/sqlalchemy/pool/base.py", line 639, in __connect
    connection = pool._invoke_creator(self)
  File "/usr/local/lib/python3.6/dist-packages/sqlalchemy/engine/strategies.py", line 114, in connect
    return dialect.connect(*cargs, **cparams)
  File "/usr/local/lib/python3.6/dist-packages/sqlalchemy/engine/default.py", line 482, in connect
    return self.dbapi.connect(*cargs, **cparams)
pyodbc.Error: ('01000', "[01000] [unixODBC][Driver Manager]Can't open lib 'SQL Server Native Client 11.0' : file not found (0) (SQLDriverConnect)")

The above exception was the direct cause of the following exception:

Traceback (most recent call last):
  File "/home/python_project/hello.py", line 74, in get
    conn = db_connect.connect()
  File "/usr/local/lib/python3.6/dist-packages/sqlalchemy/engine/base.py", line 2209, in connect
    return self._connection_cls(self, **kwargs)
  File "/usr/local/lib/python3.6/dist-packages/sqlalchemy/engine/base.py", line 103, in __init__
    else engine.raw_connection()
  File "/usr/local/lib/python3.6/dist-packages/sqlalchemy/engine/base.py", line 2307, in raw_connection
    self.pool.unique_connection, _connection
  File "/usr/local/lib/python3.6/dist-packages/sqlalchemy/engine/base.py", line 2280, in _wrap_pool_connect
    e, dialect, self
  File "/usr/local/lib/python3.6/dist-packages/sqlalchemy/engine/base.py", line 1547, in _handle_dbapi_exception_noconnection
    util.raise_from_cause(sqlalchemy_exception, exc_info)
  File "/usr/local/lib/python3.6/dist-packages/sqlalchemy/util/compat.py", line 398, in raise_from_cause
    reraise(type(exception), exception, tb=exc_tb, cause=cause)
  File "/usr/local/lib/python3.6/dist-packages/sqlalchemy/util/compat.py", line 152, in reraise
    raise value.with_traceback(tb)
  File "/usr/local/lib/python3.6/dist-packages/sqlalchemy/engine/base.py", line 2276, in _wrap_pool_connect
    return fn()
  File "/usr/local/lib/python3.6/dist-packages/sqlalchemy/pool/base.py", line 303, in unique_connection
    return _ConnectionFairy._checkout(self)
  File "/usr/local/lib/python3.6/dist-packages/sqlalchemy/pool/base.py", line 760, in _checkout
    fairy = _ConnectionRecord.checkout(pool)
  File "/usr/local/lib/python3.6/dist-packages/sqlalchemy/pool/base.py", line 492, in checkout
    rec = pool._do_get()
  File "/usr/local/lib/python3.6/dist-packages/sqlalchemy/pool/impl.py", line 139, in _do_get
    self._dec_overflow()
  File "/usr/local/lib/python3.6/dist-packages/sqlalchemy/util/langhelpers.py", line 68, in __exit__
    compat.reraise(exc_type, exc_value, exc_tb)
  File "/usr/local/lib/python3.6/dist-packages/sqlalchemy/util/compat.py", line 153, in reraise
    raise value
  File "/usr/local/lib/python3.6/dist-packages/sqlalchemy/pool/impl.py", line 136, in _do_get
    return self._create_connection()
  File "/usr/local/lib/python3.6/dist-packages/sqlalchemy/pool/base.py", line 308, in _create_connection
    return _ConnectionRecord(self)
  File "/usr/local/lib/python3.6/dist-packages/sqlalchemy/pool/base.py", line 437, in __init__
    self.__connect(first_connect_check=True)
  File "/usr/local/lib/python3.6/dist-packages/sqlalchemy/pool/base.py", line 639, in __connect
    connection = pool._invoke_creator(self)
  File "/usr/local/lib/python3.6/dist-packages/sqlalchemy/engine/strategies.py", line 114, in connect
    return dialect.connect(*cargs, **cparams)
  File "/usr/local/lib/python3.6/dist-packages/sqlalchemy/engine/default.py", line 482, in connect
    return self.dbapi.connect(*cargs, **cparams)
sqlalchemy.exc.DBAPIError: (pyodbc.Error) ('01000', "[01000] [unixODBC][Driver Manager]Can't open lib 'SQL Server Native Client 11.0' : file not found (0) (SQLDriverConnect)")
(Background on this error at: http://sqlalche.me/e/dbapi)

During handling of the above exception, another exception occurred:

Traceback (most recent call last):
  File "/usr/local/lib/python3.6/dist-packages/flask/app.py", line 1949, in full_dispatch_request
    rv = self.dispatch_request()
  File "/usr/local/lib/python3.6/dist-packages/flask/app.py", line 1935, in dispatch_request
    return self.view_functions[rule.endpoint](**req.view_args)
  File "/usr/local/lib/python3.6/dist-packages/flask_restful/__init__.py", line 458, in wrapper
    resp = resource(*args, **kwargs)
  File "/usr/local/lib/python3.6/dist-packages/flask/views.py", line 89, in view
    return self.dispatch_request(*args, **kwargs)
  File "/usr/local/lib/python3.6/dist-packages/flask_restful/__init__.py", line 573, in dispatch_request
    resp = meth(*args, **kwargs)
  File "/home/python_project/hello.py", line 88, in get
    + str(e))
UnboundLocalError: local variable 'agentUsername' referenced before assignment
Mon, 16 Dec 2019 16:45:19 - INFO - 109.245.208.129 - - [16/Dec/2019 16:45:19] "GET /records?agent=3016&caller_id=38163353865&date=20191120&time=140203 HTTP/1.1" 500 -
