Thu, 19 Dec 2019 17:52:08 - INFO - Connect to DB
Thu, 19 Dec 2019 17:52:09 - INFO - TRIZMA DB import
Thu, 19 Dec 2019 17:52:09 - INFO - Failed on TRIZMA DB import at: 2019-12-19_16-52-22, for following calling party: 493746389309, for agent id: trz_sstankovic, with error:(pyodbc.DataError) ('22001', '[22001] [Microsoft][ODBC Driver 17 for SQL Server][SQL Server]String or binary data would be truncated. (8152) (SQLExecDirectW)')
[SQL: insert into records values('CC2Servicenummer','Belgrad','Nicht übermittelt','trz_sstankovic',                                  '493746389309','','Nicht übermittelt','493746389309_Thursday, December 19, 2019_6:52:07 PM')]
(Background on this error at: http://sqlalche.me/e/9h9h)
Thu, 19 Dec 2019 17:52:09 - INFO - 123TV DB import
Fri, 20 Dec 2019 07:02:37 - INFO - Connect to DB
Fri, 20 Dec 2019 07:02:37 - ERROR - Exception on /records [GET]
Traceback (most recent call last):
  File "/home/python_project/hello.py", line 81, in get
    1)).fetchone()[0]
TypeError: 'NoneType' object is not subscriptable

During handling of the above exception, another exception occurred:

Traceback (most recent call last):
  File "/usr/local/lib/python3.6/dist-packages/flask/app.py", line 1949, in full_dispatch_request
    rv = self.dispatch_request()
  File "/usr/local/lib/python3.6/dist-packages/flask/app.py", line 1935, in dispatch_request
    return self.view_functions[rule.endpoint](**req.view_args)
  File "/usr/local/lib/python3.6/dist-packages/flask_restful/__init__.py", line 458, in wrapper
    resp = resource(*args, **kwargs)
  File "/usr/local/lib/python3.6/dist-packages/flask/views.py", line 89, in view
    return self.dispatch_request(*args, **kwargs)
  File "/usr/local/lib/python3.6/dist-packages/flask_restful/__init__.py", line 573, in dispatch_request
    resp = meth(*args, **kwargs)
  File "/home/python_project/hello.py", line 90, in get
    + str(e))
UnboundLocalError: local variable 'agentUsername' referenced before assignment
