Fri, 20 Dec 2019 12:48:26 - INFO - Connect to DB
Fri, 20 Dec 2019 12:48:27 - INFO - TRIZMA DB import
Fri, 20 Dec 2019 12:48:27 - INFO - 123TV DB import
Fri, 20 Dec 2019 12:48:32 - INFO - Failed on 123TV DB import at: 2019-12-20_11-47-01, for following calling party: %m, for agent id: 3016, with error:Call to undefined method ImportCallMetaData::Message()
Fri, 20 Dec 2019 12:57:49 - INFO - Connect to DB
Fri, 20 Dec 2019 12:57:49 - ERROR - Exception on /records [GET]
Traceback (most recent call last):
  File "/home/python_project/hello.py", line 80, in get
    int(agent),
ValueError: invalid literal for int() with base 10: ''

During handling of the above exception, another exception occurred:

Traceback (most recent call last):
  File "/usr/local/lib/python3.6/dist-packages/flask/app.py", line 1949, in full_dispatch_request
    rv = self.dispatch_request()
  File "/usr/local/lib/python3.6/dist-packages/flask/app.py", line 1935, in dispatch_request
    return self.view_functions[rule.endpoint](**req.view_args)
  File "/usr/local/lib/python3.6/dist-packages/flask_restful/__init__.py", line 458, in wrapper
    resp = resource(*args, **kwargs)
  File "/usr/local/lib/python3.6/dist-packages/flask/views.py", line 89, in view
    return self.dispatch_request(*args, **kwargs)
  File "/usr/local/lib/python3.6/dist-packages/flask_restful/__init__.py", line 573, in dispatch_request
    resp = meth(*args, **kwargs)
  File "/home/python_project/hello.py", line 90, in get
    + str(e))
UnboundLocalError: local variable 'agentUsername' referenced before assignment
Fri, 20 Dec 2019 13:21:40 - INFO - Connect to DB
Fri, 20 Dec 2019 13:21:40 - ERROR - Exception on /records [GET]
Traceback (most recent call last):
  File "/home/python_project/hello.py", line 80, in get
    int(agent),
ValueError: invalid literal for int() with base 10: ''

During handling of the above exception, another exception occurred:

Traceback (most recent call last):
  File "/usr/local/lib/python3.6/dist-packages/flask/app.py", line 1949, in full_dispatch_request
    rv = self.dispatch_request()
  File "/usr/local/lib/python3.6/dist-packages/flask/app.py", line 1935, in dispatch_request
    return self.view_functions[rule.endpoint](**req.view_args)
  File "/usr/local/lib/python3.6/dist-packages/flask_restful/__init__.py", line 458, in wrapper
    resp = resource(*args, **kwargs)
  File "/usr/local/lib/python3.6/dist-packages/flask/views.py", line 89, in view
    return self.dispatch_request(*args, **kwargs)
  File "/usr/local/lib/python3.6/dist-packages/flask_restful/__init__.py", line 573, in dispatch_request
    resp = meth(*args, **kwargs)
  File "/home/python_project/hello.py", line 90, in get
    + str(e))
UnboundLocalError: local variable 'agentUsername' referenced before assignment
Fri, 20 Dec 2019 13:23:41 - INFO - Connect to DB
Fri, 20 Dec 2019 13:23:41 - ERROR - Exception on /records [GET]
Traceback (most recent call last):
  File "/home/python_project/hello.py", line 80, in get
    int(agent),
ValueError: invalid literal for int() with base 10: ''

During handling of the above exception, another exception occurred:

Traceback (most recent call last):
  File "/usr/local/lib/python3.6/dist-packages/flask/app.py", line 1949, in full_dispatch_request
    rv = self.dispatch_request()
  File "/usr/local/lib/python3.6/dist-packages/flask/app.py", line 1935, in dispatch_request
    return self.view_functions[rule.endpoint](**req.view_args)
  File "/usr/local/lib/python3.6/dist-packages/flask_restful/__init__.py", line 458, in wrapper
    resp = resource(*args, **kwargs)
  File "/usr/local/lib/python3.6/dist-packages/flask/views.py", line 89, in view
    return self.dispatch_request(*args, **kwargs)
  File "/usr/local/lib/python3.6/dist-packages/flask_restful/__init__.py", line 573, in dispatch_request
    resp = meth(*args, **kwargs)
  File "/home/python_project/hello.py", line 90, in get
    + str(e))
UnboundLocalError: local variable 'agentUsername' referenced before assignment
