Tue, 17 Dec 2019 18:26:48 - INFO - Connect to DB
Tue, 17 Dec 2019 18:26:48 - INFO - TRIZMA DB import
Tue, 17 Dec 2019 18:26:48 - INFO - 123TV DB import
Tue, 17 Dec 2019 18:39:54 - INFO - Connect to DB
Tue, 17 Dec 2019 18:39:54 - INFO - TRIZMA DB import
Tue, 17 Dec 2019 18:39:54 - INFO - Failed on TRIZMA DB import at: 2019-12-17_18-09-43, for following calling party: 4923133026851, for agent id: trz_asilni, with error:(pyodbc.DataError) ('22001', '[22001] [Microsoft][ODBC Driver 17 for SQL Server][SQL Server]String or binary data would be truncated. (8152) (SQLExecDirectW)')
[SQL: insert into records values('CC2Servicenummer','Belgrad','Nicht übermittelt','trz_asilni',                                  '4923133026851','','Nicht übermittelt','4923133026851_Tuesday, December 17, 2019_7:39:52 PM')]
(Background on this error at: http://sqlalche.me/e/9h9h)
Tue, 17 Dec 2019 18:39:54 - INFO - 123TV DB import
Tue, 17 Dec 2019 19:02:47 - INFO - Connect to DB
Tue, 17 Dec 2019 19:02:47 - INFO - TRIZMA DB import
Tue, 17 Dec 2019 19:02:47 - INFO - 123TV DB import
Wed, 18 Dec 2019 11:03:53 - INFO - Connect to DB
Wed, 18 Dec 2019 11:03:53 - ERROR - Exception on /records [GET]
Traceback (most recent call last):
  File "/home/python_project/hello.py", line 81, in get
    1)).fetchone()[0]
TypeError: 'NoneType' object is not subscriptable

During handling of the above exception, another exception occurred:

Traceback (most recent call last):
  File "/usr/local/lib/python3.6/dist-packages/flask/app.py", line 1949, in full_dispatch_request
    rv = self.dispatch_request()
  File "/usr/local/lib/python3.6/dist-packages/flask/app.py", line 1935, in dispatch_request
    return self.view_functions[rule.endpoint](**req.view_args)
  File "/usr/local/lib/python3.6/dist-packages/flask_restful/__init__.py", line 458, in wrapper
    resp = resource(*args, **kwargs)
  File "/usr/local/lib/python3.6/dist-packages/flask/views.py", line 89, in view
    return self.dispatch_request(*args, **kwargs)
  File "/usr/local/lib/python3.6/dist-packages/flask_restful/__init__.py", line 573, in dispatch_request
    resp = meth(*args, **kwargs)
  File "/home/python_project/hello.py", line 90, in get
    + str(e))
UnboundLocalError: local variable 'agentUsername' referenced before assignment
